[INFO   ] Logger: Record log in /storage/emulated/0/MyProjects/BioGenesis/.kivy/logs/kivy_21-08-04_94.txt
[INFO   ] Kivy: v1.11.1
[INFO   ] Kivy: Installed at "/data/user/0/ru.iiec.pydroid3/files/aarch64-linux-android/lib/python3.8/site-packages/kivy/__init__.py"
[INFO   ] Python: v3.8.3 (default, May 27 2020, 02:08:17) 
[GCC 9.3.0]
[INFO   ] Python: Interpreter at "/data/user/0/ru.iiec.pydroid3/files/aarch64-linux-android/bin/python3"
[INFO   ] Factory: 184 symbols loaded
[INFO   ] KivyMD: v0.104.1
[INFO   ] Image: Providers: img_tex, img_dds, img_sdl2, img_pil, img_gif (img_ffpyplayer ignored)
[INFO   ] Window: Provider: sdl2
[INFO   ] GL: Using the "OpenGL ES 2" graphics system
[INFO   ] GL: Backend used <sdl2>
[INFO   ] GL: OpenGL version <b'OpenGL ES 3.2 V@415.0 (GIT@f345350, I0760943699, 1580221225) (Date:01/28/20)'>
[INFO   ] GL: OpenGL vendor <b'Qualcomm'>
[INFO   ] GL: OpenGL renderer <b'Adreno (TM) 504'>
[INFO   ] GL: OpenGL parsed version: 3, 2
[INFO   ] GL: Texture max size <16384>
[INFO   ] GL: Texture max units <16>
[INFO   ] Window: auto add sdl2 input provider
[INFO   ] Window: virtual keyboard not allowed, single mode, not docked
[INFO   ] Text: Provider: sdl2
[INFO   ] GL: NPOT texture support is available
[INFO   ] Loader: using a thread pool of 2 workers
[WARNING] Base: Unknown <android> provider
[INFO   ] Base: Start application main loop
[ERROR  ] Loader: Failed to load image <https://i1.wp.com/getcomics.info/share/uploads/2018/09/Avengers-Assemble-By-Brian-Michael-Bendis-2013.jpg?fit=400%2C620&ssl=1>
Traceback (most recent call last):
  File "/data/user/0/ru.iiec.pydroid3/files/aarch64-linux-android/lib/python3.8/urllib/request.py", line 1350, in do_open
    h.request(req.get_method(), req.selector, req.data, headers,
  File "/data/user/0/ru.iiec.pydroid3/files/aarch64-linux-android/lib/python3.8/http/client.py", line 1240, in request
    self._send_request(method, url, body, headers, encode_chunked)
  File "/data/user/0/ru.iiec.pydroid3/files/aarch64-linux-android/lib/python3.8/http/client.py", line 1286, in _send_request
    self.endheaders(body, encode_chunked=encode_chunked)
  File "/data/user/0/ru.iiec.pydroid3/files/aarch64-linux-android/lib/python3.8/http/client.py", line 1235, in endheaders
    self._send_output(message_body, encode_chunked=encode_chunked)
  File "/data/user/0/ru.iiec.pydroid3/files/aarch64-linux-android/lib/python3.8/http/client.py", line 1006, in _send_output
    self.send(msg)
  File "/data/user/0/ru.iiec.pydroid3/files/aarch64-linux-android/lib/python3.8/http/client.py", line 946, in send
    self.connect()
  File "/data/user/0/ru.iiec.pydroid3/files/aarch64-linux-android/lib/python3.8/http/client.py", line 1402, in connect
    super().connect()
  File "/data/user/0/ru.iiec.pydroid3/files/aarch64-linux-android/lib/python3.8/http/client.py", line 917, in connect
    self.sock = self._create_connection(
  File "/data/user/0/ru.iiec.pydroid3/files/aarch64-linux-android/lib/python3.8/socket.py", line 787, in create_connection
    for res in getaddrinfo(host, port, 0, SOCK_STREAM):
  File "/data/user/0/ru.iiec.pydroid3/files/aarch64-linux-android/lib/python3.8/socket.py", line 918, in getaddrinfo
    for res in _socket.getaddrinfo(host, port, family, type, proto, flags):
socket.gaierror: [Errno 7] No address associated with hostname

During handling of the above exception, another exception occurred:

Traceback (most recent call last):
  File "/data/user/0/ru.iiec.pydroid3/files/aarch64-linux-android/lib/python3.8/site-packages/kivy/loader.py", line 342, in _load_urllib
    fd = opener.open(request)
  File "/data/user/0/ru.iiec.pydroid3/files/aarch64-linux-android/lib/python3.8/urllib/request.py", line 525, in open
    response = self._open(req, data)
  File "/data/user/0/ru.iiec.pydroid3/files/aarch64-linux-android/lib/python3.8/urllib/request.py", line 542, in _open
    result = self._call_chain(self.handle_open, protocol, protocol +
  File "/data/user/0/ru.iiec.pydroid3/files/aarch64-linux-android/lib/python3.8/urllib/request.py", line 502, in _call_chain
    result = func(*args)
  File "/data/user/0/ru.iiec.pydroid3/files/aarch64-linux-android/lib/python3.8/urllib/request.py", line 1393, in https_open
    return self.do_open(http.client.HTTPSConnection, req,
  File "/data/user/0/ru.iiec.pydroid3/files/aarch64-linux-android/lib/python3.8/urllib/request.py", line 1353, in do_open
    raise URLError(err)
urllib.error.URLError: <urlopen error [Errno 7] No address associated with hostname>
[ERROR  ] Loader: Failed to load image <https://i2.wp.com/getcomics.info/share/uploads/2021/07/Avengers-46-2021.jpg?fit=400%2C615&ssl=1>
Traceback (most recent call last):
  File "/data/user/0/ru.iiec.pydroid3/files/aarch64-linux-android/lib/python3.8/urllib/request.py", line 1350, in do_open
    h.request(req.get_method(), req.selector, req.data, headers,
  File "/data/user/0/ru.iiec.pydroid3/files/aarch64-linux-android/lib/python3.8/http/client.py", line 1240, in request
    self._send_request(method, url, body, headers, encode_chunked)
  File "/data/user/0/ru.iiec.pydroid3/files/aarch64-linux-android/lib/python3.8/http/client.py", line 1286, in _send_request
    self.endheaders(body, encode_chunked=encode_chunked)
  File "/data/user/0/ru.iiec.pydroid3/files/aarch64-linux-android/lib/python3.8/http/client.py", line 1235, in endheaders
    self._send_output(message_body, encode_chunked=encode_chunked)
  File "/data/user/0/ru.iiec.pydroid3/files/aarch64-linux-android/lib/python3.8/http/client.py", line 1006, in _send_output
    self.send(msg)
  File "/data/user/0/ru.iiec.pydroid3/files/aarch64-linux-android/lib/python3.8/http/client.py", line 946, in send
    self.connect()
  File "/data/user/0/ru.iiec.pydroid3/files/aarch64-linux-android/lib/python3.8/http/client.py", line 1402, in connect
    super().connect()
  File "/data/user/0/ru.iiec.pydroid3/files/aarch64-linux-android/lib/python3.8/http/client.py", line 917, in connect
    self.sock = self._create_connection(
  File "/data/user/0/ru.iiec.pydroid3/files/aarch64-linux-android/lib/python3.8/socket.py", line 787, in create_connection
    for res in getaddrinfo(host, port, 0, SOCK_STREAM):
  File "/data/user/0/ru.iiec.pydroid3/files/aarch64-linux-android/lib/python3.8/socket.py", line 918, in getaddrinfo
    for res in _socket.getaddrinfo(host, port, family, type, proto, flags):
socket.gaierror: [Errno 7] No address associated with hostname

During handling of the above exception, another exception occurred:

Traceback (most recent call last):
  File "/data/user/0/ru.iiec.pydroid3/files/aarch64-linux-android/lib/python3.8/site-packages/kivy/loader.py", line 342, in _load_urllib
    fd = opener.open(request)
  File "/data/user/0/ru.iiec.pydroid3/files/aarch64-linux-android/lib/python3.8/urllib/request.py", line 525, in open
    response = self._open(req, data)
  File "/data/user/0/ru.iiec.pydroid3/files/aarch64-linux-android/lib/python3.8/urllib/request.py", line 542, in _open
    result = self._call_chain(self.handle_open, protocol, protocol +
  File "/data/user/0/ru.iiec.pydroid3/files/aarch64-linux-android/lib/python3.8/urllib/request.py", line 502, in _call_chain
    result = func(*args)
  File "/data/user/0/ru.iiec.pydroid3/files/aarch64-linux-android/lib/python3.8/urllib/request.py", line 1393, in https_open
    return self.do_open(http.client.HTTPSConnection, req,
  File "/data/user/0/ru.iiec.pydroid3/files/aarch64-linux-android/lib/python3.8/urllib/request.py", line 1353, in do_open
    raise URLError(err)
urllib.error.URLError: <urlopen error [Errno 7] No address associated with hostname>
[ERROR  ] Loader: Failed to load image <https://i2.wp.com/getcomics.info/share/uploads/2021/07/Savage-Avengers-Vol.-3-Enter-The-Dragon-TPB-2021.jpg?fit=400%2C615&ssl=1>
Traceback (most recent call last):
  File "/data/user/0/ru.iiec.pydroid3/files/aarch64-linux-android/lib/python3.8/urllib/request.py", line 1350, in do_open
    h.request(req.get_method(), req.selector, req.data, headers,
  File "/data/user/0/ru.iiec.pydroid3/files/aarch64-linux-android/lib/python3.8/http/client.py", line 1240, in request
    self._send_request(method, url, body, headers, encode_chunked)
  File "/data/user/0/ru.iiec.pydroid3/files/aarch64-linux-android/lib/python3.8/http/client.py", line 1286, in _send_request
    self.endheaders(body, encode_chunked=encode_chunked)
  File "/data/user/0/ru.iiec.pydroid3/files/aarch64-linux-android/lib/python3.8/http/client.py", line 1235, in endheaders
    self._send_output(message_body, encode_chunked=encode_chunked)
  File "/data/user/0/ru.iiec.pydroid3/files/aarch64-linux-android/lib/python3.8/http/client.py", line 1006, in _send_output
    self.send(msg)
  File "/data/user/0/ru.iiec.pydroid3/files/aarch64-linux-android/lib/python3.8/http/client.py", line 946, in send
    self.connect()
  File "/data/user/0/ru.iiec.pydroid3/files/aarch64-linux-android/lib/python3.8/http/client.py", line 1402, in connect
    super().connect()
  File "/data/user/0/ru.iiec.pydroid3/files/aarch64-linux-android/lib/python3.8/http/client.py", line 917, in connect
    self.sock = self._create_connection(
  File "/data/user/0/ru.iiec.pydroid3/files/aarch64-linux-android/lib/python3.8/socket.py", line 787, in create_connection
    for res in getaddrinfo(host, port, 0, SOCK_STREAM):
  File "/data/user/0/ru.iiec.pydroid3/files/aarch64-linux-android/lib/python3.8/socket.py", line 918, in getaddrinfo
    for res in _socket.getaddrinfo(host, port, family, type, proto, flags):
socket.gaierror: [Errno 7] No address associated with hostname

During handling of the above exception, another exception occurred:

Traceback (most recent call last):
  File "/data/user/0/ru.iiec.pydroid3/files/aarch64-linux-android/lib/python3.8/site-packages/kivy/loader.py", line 342, in _load_urllib
    fd = opener.open(request)
  File "/data/user/0/ru.iiec.pydroid3/files/aarch64-linux-android/lib/python3.8/urllib/request.py", line 525, in open
    response = self._open(req, data)
  File "/data/user/0/ru.iiec.pydroid3/files/aarch64-linux-android/lib/python3.8/urllib/request.py", line 542, in _open
    result = self._call_chain(self.handle_open, protocol, protocol +
  File "/data/user/0/ru.iiec.pydroid3/files/aarch64-linux-android/lib/python3.8/urllib/request.py", line 502, in _call_chain
    result = func(*args)
  File "/data/user/0/ru.iiec.pydroid3/files/aarch64-linux-android/lib/python3.8/urllib/request.py", line 1393, in https_open
    return self.do_open(http.client.HTTPSConnection, req,
  File "/data/user/0/ru.iiec.pydroid3/files/aarch64-linux-android/lib/python3.8/urllib/request.py", line 1353, in do_open
    raise URLError(err)
urllib.error.URLError: <urlopen error [Errno 7] No address associated with hostname>
[ERROR  ] Loader: Failed to load image <https://i1.wp.com/getcomics.info/share/uploads/2018/01/X-Men-vs.-Avengers-TPB-2016.jpg?fit=400%2C615&ssl=1>
Traceback (most recent call last):
  File "/data/user/0/ru.iiec.pydroid3/files/aarch64-linux-android/lib/python3.8/urllib/request.py", line 1350, in do_open
    h.request(req.get_method(), req.selector, req.data, headers,
  File "/data/user/0/ru.iiec.pydroid3/files/aarch64-linux-android/lib/python3.8/http/client.py", line 1240, in request
    self._send_request(method, url, body, headers, encode_chunked)
  File "/data/user/0/ru.iiec.pydroid3/files/aarch64-linux-android/lib/python3.8/http/client.py", line 1286, in _send_request
    self.endheaders(body, encode_chunked=encode_chunked)
  File "/data/user/0/ru.iiec.pydroid3/files/aarch64-linux-android/lib/python3.8/http/client.py", line 1235, in endheaders
    self._send_output(message_body, encode_chunked=encode_chunked)
  File "/data/user/0/ru.iiec.pydroid3/files/aarch64-linux-android/lib/python3.8/http/client.py", line 1006, in _send_output
    self.send(msg)
  File "/data/user/0/ru.iiec.pydroid3/files/aarch64-linux-android/lib/python3.8/http/client.py", line 946, in send
    self.connect()
  File "/data/user/0/ru.iiec.pydroid3/files/aarch64-linux-android/lib/python3.8/http/client.py", line 1402, in connect
    super().connect()
  File "/data/user/0/ru.iiec.pydroid3/files/aarch64-linux-android/lib/python3.8/http/client.py", line 917, in connect
    self.sock = self._create_connection(
  File "/data/user/0/ru.iiec.pydroid3/files/aarch64-linux-android/lib/python3.8/socket.py", line 787, in create_connection
    for res in getaddrinfo(host, port, 0, SOCK_STREAM):
  File "/data/user/0/ru.iiec.pydroid3/files/aarch64-linux-android/lib/python3.8/socket.py", line 918, in getaddrinfo
    for res in _socket.getaddrinfo(host, port, family, type, proto, flags):
socket.gaierror: [Errno 7] No address associated with hostname

During handling of the above exception, another exception occurred:

Traceback (most recent call last):
  File "/data/user/0/ru.iiec.pydroid3/files/aarch64-linux-android/lib/python3.8/site-packages/kivy/loader.py", line 342, in _load_urllib
    fd = opener.open(request)
  File "/data/user/0/ru.iiec.pydroid3/files/aarch64-linux-android/lib/python3.8/urllib/request.py", line 525, in open
    response = self._open(req, data)
  File "/data/user/0/ru.iiec.pydroid3/files/aarch64-linux-android/lib/python3.8/urllib/request.py", line 542, in _open
    result = self._call_chain(self.handle_open, protocol, protocol +
  File "/data/user/0/ru.iiec.pydroid3/files/aarch64-linux-android/lib/python3.8/urllib/request.py", line 502, in _call_chain
    result = func(*args)
  File "/data/user/0/ru.iiec.pydroid3/files/aarch64-linux-android/lib/python3.8/urllib/request.py", line 1393, in https_open
    return self.do_open(http.client.HTTPSConnection, req,
  File "/data/user/0/ru.iiec.pydroid3/files/aarch64-linux-android/lib/python3.8/urllib/request.py", line 1353, in do_open
    raise URLError(err)
urllib.error.URLError: <urlopen error [Errno 7] No address associated with hostname>
[ERROR  ] Loader: Failed to load image <https://i1.wp.com/getcomics.info/share/uploads/2018/01/Avengers-Vs.-X-Men-Collected-Edition-2013.jpg?fit=400%2C620&ssl=1>
Traceback (most recent call last):
  File "/data/user/0/ru.iiec.pydroid3/files/aarch64-linux-android/lib/python3.8/urllib/request.py", line 1350, in do_open
    h.request(req.get_method(), req.selector, req.data, headers,
  File "/data/user/0/ru.iiec.pydroid3/files/aarch64-linux-android/lib/python3.8/http/client.py", line 1240, in request
    self._send_request(method, url, body, headers, encode_chunked)
  File "/data/user/0/ru.iiec.pydroid3/files/aarch64-linux-android/lib/python3.8/http/client.py", line 1286, in _send_request
    self.endheaders(body, encode_chunked=encode_chunked)
  File "/data/user/0/ru.iiec.pydroid3/files/aarch64-linux-android/lib/python3.8/http/client.py", line 1235, in endheaders
    self._send_output(message_body, encode_chunked=encode_chunked)
  File "/data/user/0/ru.iiec.pydroid3/files/aarch64-linux-android/lib/python3.8/http/client.py", line 1006, in _send_output
    self.send(msg)
  File "/data/user/0/ru.iiec.pydroid3/files/aarch64-linux-android/lib/python3.8/http/client.py", line 946, in send
    self.connect()
  File "/data/user/0/ru.iiec.pydroid3/files/aarch64-linux-android/lib/python3.8/http/client.py", line 1402, in connect
    super().connect()
  File "/data/user/0/ru.iiec.pydroid3/files/aarch64-linux-android/lib/python3.8/http/client.py", line 917, in connect
    self.sock = self._create_connection(
  File "/data/user/0/ru.iiec.pydroid3/files/aarch64-linux-android/lib/python3.8/socket.py", line 787, in create_connection
    for res in getaddrinfo(host, port, 0, SOCK_STREAM):
  File "/data/user/0/ru.iiec.pydroid3/files/aarch64-linux-android/lib/python3.8/socket.py", line 918, in getaddrinfo
    for res in _socket.getaddrinfo(host, port, family, type, proto, flags):
socket.gaierror: [Errno 7] No address associated with hostname

During handling of the above exception, another exception occurred:

Traceback (most recent call last):
  File "/data/user/0/ru.iiec.pydroid3/files/aarch64-linux-android/lib/python3.8/site-packages/kivy/loader.py", line 342, in _load_urllib
    fd = opener.open(request)
  File "/data/user/0/ru.iiec.pydroid3/files/aarch64-linux-android/lib/python3.8/urllib/request.py", line 525, in open
    response = self._open(req, data)
  File "/data/user/0/ru.iiec.pydroid3/files/aarch64-linux-android/lib/python3.8/urllib/request.py", line 542, in _open
    result = self._call_chain(self.handle_open, protocol, protocol +
  File "/data/user/0/ru.iiec.pydroid3/files/aarch64-linux-android/lib/python3.8/urllib/request.py", line 502, in _call_chain
    result = func(*args)
  File "/data/user/0/ru.iiec.pydroid3/files/aarch64-linux-android/lib/python3.8/urllib/request.py", line 1393, in https_open
    return self.do_open(http.client.HTTPSConnection, req,
  File "/data/user/0/ru.iiec.pydroid3/files/aarch64-linux-android/lib/python3.8/urllib/request.py", line 1353, in do_open
    raise URLError(err)
urllib.error.URLError: <urlopen error [Errno 7] No address associated with hostname>
[ERROR  ] Loader: Failed to load image <https://i1.wp.com/getcomics.info/share/uploads/2021/07/Avengers-vs.-X-Men-VS-TPB-2013.jpg?fit=400%2C615&ssl=1>
Traceback (most recent call last):
  File "/data/user/0/ru.iiec.pydroid3/files/aarch64-linux-android/lib/python3.8/urllib/request.py", line 1350, in do_open
    h.request(req.get_method(), req.selector, req.data, headers,
  File "/data/user/0/ru.iiec.pydroid3/files/aarch64-linux-android/lib/python3.8/http/client.py", line 1240, in request
    self._send_request(method, url, body, headers, encode_chunked)
  File "/data/user/0/ru.iiec.pydroid3/files/aarch64-linux-android/lib/python3.8/http/client.py", line 1286, in _send_request
    self.endheaders(body, encode_chunked=encode_chunked)
  File "/data/user/0/ru.iiec.pydroid3/files/aarch64-linux-android/lib/python3.8/http/client.py", line 1235, in endheaders
    self._send_output(message_body, encode_chunked=encode_chunked)
  File "/data/user/0/ru.iiec.pydroid3/files/aarch64-linux-android/lib/python3.8/http/client.py", line 1006, in _send_output
    self.send(msg)
  File "/data/user/0/ru.iiec.pydroid3/files/aarch64-linux-android/lib/python3.8/http/client.py", line 946, in send
    self.connect()
  File "/data/user/0/ru.iiec.pydroid3/files/aarch64-linux-android/lib/python3.8/http/client.py", line 1402, in connect
    super().connect()
  File "/data/user/0/ru.iiec.pydroid3/files/aarch64-linux-android/lib/python3.8/http/client.py", line 917, in connect
    self.sock = self._create_connection(
  File "/data/user/0/ru.iiec.pydroid3/files/aarch64-linux-android/lib/python3.8/socket.py", line 787, in create_connection
    for res in getaddrinfo(host, port, 0, SOCK_STREAM):
  File "/data/user/0/ru.iiec.pydroid3/files/aarch64-linux-android/lib/python3.8/socket.py", line 918, in getaddrinfo
    for res in _socket.getaddrinfo(host, port, family, type, proto, flags):
socket.gaierror: [Errno 7] No address associated with hostname

During handling of the above exception, another exception occurred:

Traceback (most recent call last):
  File "/data/user/0/ru.iiec.pydroid3/files/aarch64-linux-android/lib/python3.8/site-packages/kivy/loader.py", line 342, in _load_urllib
    fd = opener.open(request)
  File "/data/user/0/ru.iiec.pydroid3/files/aarch64-linux-android/lib/python3.8/urllib/request.py", line 525, in open
    response = self._open(req, data)
  File "/data/user/0/ru.iiec.pydroid3/files/aarch64-linux-android/lib/python3.8/urllib/request.py", line 542, in _open
    result = self._call_chain(self.handle_open, protocol, protocol +
  File "/data/user/0/ru.iiec.pydroid3/files/aarch64-linux-android/lib/python3.8/urllib/request.py", line 502, in _call_chain
    result = func(*args)
  File "/data/user/0/ru.iiec.pydroid3/files/aarch64-linux-android/lib/python3.8/urllib/request.py", line 1393, in https_open
    return self.do_open(http.client.HTTPSConnection, req,
  File "/data/user/0/ru.iiec.pydroid3/files/aarch64-linux-android/lib/python3.8/urllib/request.py", line 1353, in do_open
    raise URLError(err)
urllib.error.URLError: <urlopen error [Errno 7] No address associated with hostname>
[ERROR  ] Loader: Failed to load image <https://i2.wp.com/getcomics.info/share/uploads/2021/06/Avengers-By-Jason-Aaron-Vol.-8-Enter-The-Phoenix-TPB-2021.jpg?fit=400%2C615&ssl=1>
Traceback (most recent call last):
  File "/data/user/0/ru.iiec.pydroid3/files/aarch64-linux-android/lib/python3.8/urllib/request.py", line 1350, in do_open
    h.request(req.get_method(), req.selector, req.data, headers,
  File "/data/user/0/ru.iiec.pydroid3/files/aarch64-linux-android/lib/python3.8/http/client.py", line 1240, in request
    self._send_request(method, url, body, headers, encode_chunked)
  File "/data/user/0/ru.iiec.pydroid3/files/aarch64-linux-android/lib/python3.8/http/client.py", line 1286, in _send_request
    self.endheaders(body, encode_chunked=encode_chunked)
  File "/data/user/0/ru.iiec.pydroid3/files/aarch64-linux-android/lib/python3.8/http/client.py", line 1235, in endheaders
    self._send_output(message_body, encode_chunked=encode_chunked)
  File "/data/user/0/ru.iiec.pydroid3/files/aarch64-linux-android/lib/python3.8/http/client.py", line 1006, in _send_output
    self.send(msg)
  File "/data/user/0/ru.iiec.pydroid3/files/aarch64-linux-android/lib/python3.8/http/client.py", line 946, in send
    self.connect()
  File "/data/user/0/ru.iiec.pydroid3/files/aarch64-linux-android/lib/python3.8/http/client.py", line 1402, in connect
    super().connect()
  File "/data/user/0/ru.iiec.pydroid3/files/aarch64-linux-android/lib/python3.8/http/client.py", line 917, in connect
    self.sock = self._create_connection(
  File "/data/user/0/ru.iiec.pydroid3/files/aarch64-linux-android/lib/python3.8/socket.py", line 787, in create_connection
    for res in getaddrinfo(host, port, 0, SOCK_STREAM):
  File "/data/user/0/ru.iiec.pydroid3/files/aarch64-linux-android/lib/python3.8/socket.py", line 918, in getaddrinfo
    for res in _socket.getaddrinfo(host, port, family, type, proto, flags):
socket.gaierror: [Errno 7] No address associated with hostname

During handling of the above exception, another exception occurred:

Traceback (most recent call last):
  File "/data/user/0/ru.iiec.pydroid3/files/aarch64-linux-android/lib/python3.8/site-packages/kivy/loader.py", line 342, in _load_urllib
    fd = opener.open(request)
  File "/data/user/0/ru.iiec.pydroid3/files/aarch64-linux-android/lib/python3.8/urllib/request.py", line 525, in open
    response = self._open(req, data)
  File "/data/user/0/ru.iiec.pydroid3/files/aarch64-linux-android/lib/python3.8/urllib/request.py", line 542, in _open
    result = self._call_chain(self.handle_open, protocol, protocol +
  File "/data/user/0/ru.iiec.pydroid3/files/aarch64-linux-android/lib/python3.8/urllib/request.py", line 502, in _call_chain
    result = func(*args)
  File "/data/user/0/ru.iiec.pydroid3/files/aarch64-linux-android/lib/python3.8/urllib/request.py", line 1393, in https_open
    return self.do_open(http.client.HTTPSConnection, req,
  File "/data/user/0/ru.iiec.pydroid3/files/aarch64-linux-android/lib/python3.8/urllib/request.py", line 1353, in do_open
    raise URLError(err)
urllib.error.URLError: <urlopen error [Errno 7] No address associated with hostname>
[ERROR  ] Loader: Failed to load image <https://i0.wp.com/getcomics.info/share/uploads/2021/06/Avengers-Mech-Strike-4-2021.jpg?fit=400%2C615&ssl=1>
Traceback (most recent call last):
  File "/data/user/0/ru.iiec.pydroid3/files/aarch64-linux-android/lib/python3.8/urllib/request.py", line 1350, in do_open
    h.request(req.get_method(), req.selector, req.data, headers,
  File "/data/user/0/ru.iiec.pydroid3/files/aarch64-linux-android/lib/python3.8/http/client.py", line 1240, in request
    self._send_request(method, url, body, headers, encode_chunked)
  File "/data/user/0/ru.iiec.pydroid3/files/aarch64-linux-android/lib/python3.8/http/client.py", line 1286, in _send_request
    self.endheaders(body, encode_chunked=encode_chunked)
  File "/data/user/0/ru.iiec.pydroid3/files/aarch64-linux-android/lib/python3.8/http/client.py", line 1235, in endheaders
    self._send_output(message_body, encode_chunked=encode_chunked)
  File "/data/user/0/ru.iiec.pydroid3/files/aarch64-linux-android/lib/python3.8/http/client.py", line 1006, in _send_output
    self.send(msg)
  File "/data/user/0/ru.iiec.pydroid3/files/aarch64-linux-android/lib/python3.8/http/client.py", line 946, in send
    self.connect()
  File "/data/user/0/ru.iiec.pydroid3/files/aarch64-linux-android/lib/python3.8/http/client.py", line 1402, in connect
    super().connect()
  File "/data/user/0/ru.iiec.pydroid3/files/aarch64-linux-android/lib/python3.8/http/client.py", line 917, in connect
    self.sock = self._create_connection(
  File "/data/user/0/ru.iiec.pydroid3/files/aarch64-linux-android/lib/python3.8/socket.py", line 787, in create_connection
    for res in getaddrinfo(host, port, 0, SOCK_STREAM):
  File "/data/user/0/ru.iiec.pydroid3/files/aarch64-linux-android/lib/python3.8/socket.py", line 918, in getaddrinfo
    for res in _socket.getaddrinfo(host, port, family, type, proto, flags):
socket.gaierror: [Errno 7] No address associated with hostname

During handling of the above exception, another exception occurred:

Traceback (most recent call last):
  File "/data/user/0/ru.iiec.pydroid3/files/aarch64-linux-android/lib/python3.8/site-packages/kivy/loader.py", line 342, in _load_urllib
    fd = opener.open(request)
  File "/data/user/0/ru.iiec.pydroid3/files/aarch64-linux-android/lib/python3.8/urllib/request.py", line 525, in open
    response = self._open(req, data)
  File "/data/user/0/ru.iiec.pydroid3/files/aarch64-linux-android/lib/python3.8/urllib/request.py", line 542, in _open
    result = self._call_chain(self.handle_open, protocol, protocol +
  File "/data/user/0/ru.iiec.pydroid3/files/aarch64-linux-android/lib/python3.8/urllib/request.py", line 502, in _call_chain
    result = func(*args)
  File "/data/user/0/ru.iiec.pydroid3/files/aarch64-linux-android/lib/python3.8/urllib/request.py", line 1393, in https_open
    return self.do_open(http.client.HTTPSConnection, req,
  File "/data/user/0/ru.iiec.pydroid3/files/aarch64-linux-android/lib/python3.8/urllib/request.py", line 1353, in do_open
    raise URLError(err)
urllib.error.URLError: <urlopen error [Errno 7] No address associated with hostname>
[ERROR  ] Loader: Failed to load image <https://i1.wp.com/getcomics.info/share/uploads/2021/06/Heroes-Reborn-Avengers-2020-Omnibus.jpg?fit=400%2C615&ssl=1>
Traceback (most recent call last):
  File "/data/user/0/ru.iiec.pydroid3/files/aarch64-linux-android/lib/python3.8/urllib/request.py", line 1350, in do_open
    h.request(req.get_method(), req.selector, req.data, headers,
  File "/data/user/0/ru.iiec.pydroid3/files/aarch64-linux-android/lib/python3.8/http/client.py", line 1240, in request
    self._send_request(method, url, body, headers, encode_chunked)
  File "/data/user/0/ru.iiec.pydroid3/files/aarch64-linux-android/lib/python3.8/http/client.py", line 1286, in _send_request
    self.endheaders(body, encode_chunked=encode_chunked)
  File "/data/user/0/ru.iiec.pydroid3/files/aarch64-linux-android/lib/python3.8/http/client.py", line 1235, in endheaders
    self._send_output(message_body, encode_chunked=encode_chunked)
  File "/data/user/0/ru.iiec.pydroid3/files/aarch64-linux-android/lib/python3.8/http/client.py", line 1006, in _send_output
    self.send(msg)
  File "/data/user/0/ru.iiec.pydroid3/files/aarch64-linux-android/lib/python3.8/http/client.py", line 946, in send
    self.connect()
  File "/data/user/0/ru.iiec.pydroid3/files/aarch64-linux-android/lib/python3.8/http/client.py", line 1402, in connect
    super().connect()
  File "/data/user/0/ru.iiec.pydroid3/files/aarch64-linux-android/lib/python3.8/http/client.py", line 917, in connect
    self.sock = self._create_connection(
  File "/data/user/0/ru.iiec.pydroid3/files/aarch64-linux-android/lib/python3.8/socket.py", line 787, in create_connection
    for res in getaddrinfo(host, port, 0, SOCK_STREAM):
  File "/data/user/0/ru.iiec.pydroid3/files/aarch64-linux-android/lib/python3.8/socket.py", line 918, in getaddrinfo
    for res in _socket.getaddrinfo(host, port, family, type, proto, flags):
socket.gaierror: [Errno 7] No address associated with hostname

During handling of the above exception, another exception occurred:

Traceback (most recent call last):
  File "/data/user/0/ru.iiec.pydroid3/files/aarch64-linux-android/lib/python3.8/site-packages/kivy/loader.py", line 342, in _load_urllib
    fd = opener.open(request)
  File "/data/user/0/ru.iiec.pydroid3/files/aarch64-linux-android/lib/python3.8/urllib/request.py", line 525, in open
    response = self._open(req, data)
  File "/data/user/0/ru.iiec.pydroid3/files/aarch64-linux-android/lib/python3.8/urllib/request.py", line 542, in _open
    result = self._call_chain(self.handle_open, protocol, protocol +
  File "/data/user/0/ru.iiec.pydroid3/files/aarch64-linux-android/lib/python3.8/urllib/request.py", line 502, in _call_chain
    result = func(*args)
  File "/data/user/0/ru.iiec.pydroid3/files/aarch64-linux-android/lib/python3.8/urllib/request.py", line 1393, in https_open
    return self.do_open(http.client.HTTPSConnection, req,
  File "/data/user/0/ru.iiec.pydroid3/files/aarch64-linux-android/lib/python3.8/urllib/request.py", line 1353, in do_open
    raise URLError(err)
urllib.error.URLError: <urlopen error [Errno 7] No address associated with hostname>
[ERROR  ] Loader: Failed to load image <https://i1.wp.com/getcomics.info/share/uploads/2021/06/Avengers-Forever-TPB-2018.jpg?fit=400%2C615&ssl=1>
Traceback (most recent call last):
  File "/data/user/0/ru.iiec.pydroid3/files/aarch64-linux-android/lib/python3.8/urllib/request.py", line 1350, in do_open
    h.request(req.get_method(), req.selector, req.data, headers,
  File "/data/user/0/ru.iiec.pydroid3/files/aarch64-linux-android/lib/python3.8/http/client.py", line 1240, in request
    self._send_request(method, url, body, headers, encode_chunked)
  File "/data/user/0/ru.iiec.pydroid3/files/aarch64-linux-android/lib/python3.8/http/client.py", line 1286, in _send_request
    self.endheaders(body, encode_chunked=encode_chunked)
  File "/data/user/0/ru.iiec.pydroid3/files/aarch64-linux-android/lib/python3.8/http/client.py", line 1235, in endheaders
    self._send_output(message_body, encode_chunked=encode_chunked)
  File "/data/user/0/ru.iiec.pydroid3/files/aarch64-linux-android/lib/python3.8/http/client.py", line 1006, in _send_output
    self.send(msg)
  File "/data/user/0/ru.iiec.pydroid3/files/aarch64-linux-android/lib/python3.8/http/client.py", line 946, in send
    self.connect()
  File "/data/user/0/ru.iiec.pydroid3/files/aarch64-linux-android/lib/python3.8/http/client.py", line 1402, in connect
    super().connect()
  File "/data/user/0/ru.iiec.pydroid3/files/aarch64-linux-android/lib/python3.8/http/client.py", line 917, in connect
    self.sock = self._create_connection(
  File "/data/user/0/ru.iiec.pydroid3/files/aarch64-linux-android/lib/python3.8/socket.py", line 787, in create_connection
    for res in getaddrinfo(host, port, 0, SOCK_STREAM):
  File "/data/user/0/ru.iiec.pydroid3/files/aarch64-linux-android/lib/python3.8/socket.py", line 918, in getaddrinfo
    for res in _socket.getaddrinfo(host, port, family, type, proto, flags):
socket.gaierror: [Errno 7] No address associated with hostname

During handling of the above exception, another exception occurred:

Traceback (most recent call last):
  File "/data/user/0/ru.iiec.pydroid3/files/aarch64-linux-android/lib/python3.8/site-packages/kivy/loader.py", line 342, in _load_urllib
    fd = opener.open(request)
  File "/data/user/0/ru.iiec.pydroid3/files/aarch64-linux-android/lib/python3.8/urllib/request.py", line 525, in open
    response = self._open(req, data)
  File "/data/user/0/ru.iiec.pydroid3/files/aarch64-linux-android/lib/python3.8/urllib/request.py", line 542, in _open
    result = self._call_chain(self.handle_open, protocol, protocol +
  File "/data/user/0/ru.iiec.pydroid3/files/aarch64-linux-android/lib/python3.8/urllib/request.py", line 502, in _call_chain
    result = func(*args)
  File "/data/user/0/ru.iiec.pydroid3/files/aarch64-linux-android/lib/python3.8/urllib/request.py", line 1393, in https_open
    return self.do_open(http.client.HTTPSConnection, req,
  File "/data/user/0/ru.iiec.pydroid3/files/aarch64-linux-android/lib/python3.8/urllib/request.py", line 1353, in do_open
    raise URLError(err)
urllib.error.URLError: <urlopen error [Errno 7] No address associated with hostname>
[ERROR  ] Loader: Failed to load image <https://i2.wp.com/getcomics.info/share/uploads/2021/06/Savage-Avengers-21-2021.jpg?fit=400%2C615&ssl=1>
Traceback (most recent call last):
  File "/data/user/0/ru.iiec.pydroid3/files/aarch64-linux-android/lib/python3.8/urllib/request.py", line 1350, in do_open
    h.request(req.get_method(), req.selector, req.data, headers,
  File "/data/user/0/ru.iiec.pydroid3/files/aarch64-linux-android/lib/python3.8/http/client.py", line 1240, in request
    self._send_request(method, url, body, headers, encode_chunked)
  File "/data/user/0/ru.iiec.pydroid3/files/aarch64-linux-android/lib/python3.8/http/client.py", line 1286, in _send_request
    self.endheaders(body, encode_chunked=encode_chunked)
  File "/data/user/0/ru.iiec.pydroid3/files/aarch64-linux-android/lib/python3.8/http/client.py", line 1235, in endheaders
    self._send_output(message_body, encode_chunked=encode_chunked)
  File "/data/user/0/ru.iiec.pydroid3/files/aarch64-linux-android/lib/python3.8/http/client.py", line 1006, in _send_output
    self.send(msg)
  File "/data/user/0/ru.iiec.pydroid3/files/aarch64-linux-android/lib/python3.8/http/client.py", line 946, in send
    self.connect()
  File "/data/user/0/ru.iiec.pydroid3/files/aarch64-linux-android/lib/python3.8/http/client.py", line 1402, in connect
    super().connect()
  File "/data/user/0/ru.iiec.pydroid3/files/aarch64-linux-android/lib/python3.8/http/client.py", line 917, in connect
    self.sock = self._create_connection(
  File "/data/user/0/ru.iiec.pydroid3/files/aarch64-linux-android/lib/python3.8/socket.py", line 787, in create_connection
    for res in getaddrinfo(host, port, 0, SOCK_STREAM):
  File "/data/user/0/ru.iiec.pydroid3/files/aarch64-linux-android/lib/python3.8/socket.py", line 918, in getaddrinfo
    for res in _socket.getaddrinfo(host, port, family, type, proto, flags):
socket.gaierror: [Errno 7] No address associated with hostname

During handling of the above exception, another exception occurred:

Traceback (most recent call last):
  File "/data/user/0/ru.iiec.pydroid3/files/aarch64-linux-android/lib/python3.8/site-packages/kivy/loader.py", line 342, in _load_urllib
    fd = opener.open(request)
  File "/data/user/0/ru.iiec.pydroid3/files/aarch64-linux-android/lib/python3.8/urllib/request.py", line 525, in open
    response = self._open(req, data)
  File "/data/user/0/ru.iiec.pydroid3/files/aarch64-linux-android/lib/python3.8/urllib/request.py", line 542, in _open
    result = self._call_chain(self.handle_open, protocol, protocol +
  File "/data/user/0/ru.iiec.pydroid3/files/aarch64-linux-android/lib/python3.8/urllib/request.py", line 502, in _call_chain
    result = func(*args)
  File "/data/user/0/ru.iiec.pydroid3/files/aarch64-linux-android/lib/python3.8/urllib/request.py", line 1393, in https_open
    return self.do_open(http.client.HTTPSConnection, req,
  File "/data/user/0/ru.iiec.pydroid3/files/aarch64-linux-android/lib/python3.8/urllib/request.py", line 1353, in do_open
    raise URLError(err)
urllib.error.URLError: <urlopen error [Errno 7] No address associated with hostname>
[ERROR  ] Loader: Failed to load image <https://i2.wp.com/getcomics.info/share/uploads/2021/05/Savage-Avengers-Vol.-2-To-Dine-With-Doom-TPB-2020.jpg?fit=400%2C615&ssl=1>
Traceback (most recent call last):
  File "/data/user/0/ru.iiec.pydroid3/files/aarch64-linux-android/lib/python3.8/urllib/request.py", line 1350, in do_open
    h.request(req.get_method(), req.selector, req.data, headers,
  File "/data/user/0/ru.iiec.pydroid3/files/aarch64-linux-android/lib/python3.8/http/client.py", line 1240, in request
    self._send_request(method, url, body, headers, encode_chunked)
  File "/data/user/0/ru.iiec.pydroid3/files/aarch64-linux-android/lib/python3.8/http/client.py", line 1286, in _send_request
    self.endheaders(body, encode_chunked=encode_chunked)
  File "/data/user/0/ru.iiec.pydroid3/files/aarch64-linux-android/lib/python3.8/http/client.py", line 1235, in endheaders
    self._send_output(message_body, encode_chunked=encode_chunked)
  File "/data/user/0/ru.iiec.pydroid3/files/aarch64-linux-android/lib/python3.8/http/client.py", line 1006, in _send_output
    self.send(msg)
  File "/data/user/0/ru.iiec.pydroid3/files/aarch64-linux-android/lib/python3.8/http/client.py", line 946, in send
    self.connect()
  File "/data/user/0/ru.iiec.pydroid3/files/aarch64-linux-android/lib/python3.8/http/client.py", line 1402, in connect
    super().connect()
  File "/data/user/0/ru.iiec.pydroid3/files/aarch64-linux-android/lib/python3.8/http/client.py", line 917, in connect
    self.sock = self._create_connection(
  File "/data/user/0/ru.iiec.pydroid3/files/aarch64-linux-android/lib/python3.8/socket.py", line 787, in create_connection
    for res in getaddrinfo(host, port, 0, SOCK_STREAM):
  File "/data/user/0/ru.iiec.pydroid3/files/aarch64-linux-android/lib/python3.8/socket.py", line 918, in getaddrinfo
    for res in _socket.getaddrinfo(host, port, family, type, proto, flags):
socket.gaierror: [Errno 7] No address associated with hostname

During handling of the above exception, another exception occurred:

Traceback (most recent call last):
  File "/data/user/0/ru.iiec.pydroid3/files/aarch64-linux-android/lib/python3.8/site-packages/kivy/loader.py", line 342, in _load_urllib
    fd = opener.open(request)
  File "/data/user/0/ru.iiec.pydroid3/files/aarch64-linux-android/lib/python3.8/urllib/request.py", line 525, in open
    response = self._open(req, data)
  File "/data/user/0/ru.iiec.pydroid3/files/aarch64-linux-android/lib/python3.8/urllib/request.py", line 542, in _open
    result = self._call_chain(self.handle_open, protocol, protocol +
  File "/data/user/0/ru.iiec.pydroid3/files/aarch64-linux-android/lib/python3.8/urllib/request.py", line 502, in _call_chain
    result = func(*args)
  File "/data/user/0/ru.iiec.pydroid3/files/aarch64-linux-android/lib/python3.8/urllib/request.py", line 1393, in https_open
    return self.do_open(http.client.HTTPSConnection, req,
  File "/data/user/0/ru.iiec.pydroid3/files/aarch64-linux-android/lib/python3.8/urllib/request.py", line 1353, in do_open
    raise URLError(err)
urllib.error.URLError: <urlopen error [Errno 7] No address associated with hostname>
[INFO   ] Base: Leaving application in progress...
